Workbook
Name ValidEducationOptions: #REF!
Name years: #REF!
Name years: 'Items for drop down menu'!$A$69:$A$149
Name years1: 'Items for drop down menu'!$A$68:$A$149

Sheet Information
A1: FAMILY SERVICE INFORMATION SHEET
A3: Contract #: | N3: Funeral Home of Origin:
E5: First | L5: Middle | R5: Last | Y5: Family Service Director
A6: Deceased:
A8: Date of Birth: | L8: ="Age: "& CHAR(10) &DATEDIF($F$8,$F$10,"Y")&" Years "& CHAR(10)&DATEDIF($F$8,$F$10,"YM")&" Months" -> Age: 0 Years 0 Months | R8: Arrangement Date:
A10: Date of Death: | Q10: Funeral Date/Time:
A12: Funeral Director: | P12: Interment Date/Time:
A15: Purchaser: | R15: Relationship:
A17: Street Address: | S17: City:
A19: State: | G19: Zip Code: | P19: Home Phone #:
A21: Cell Phone # | O21: Email address:
A25: Co-Purchaser: | R25: Relationship:
A27: Street Address: | S27: City:
A29: State: | G29: Zip Code: | P29: Home Phone #:
A31: Cell Phone # | O31: Email address:
A34: Preferred method of daytime contact? Please include exact complete preferred contact information (i.e. If email is preferred, type in email address here. If phone is preferred, put number here. If preferred contact is someone other than the informant, please list that name and preferred contact information here.
A42: Property location: | V42: Vault:
B44: Memorial: | Q44: Open / Close:
A46: Others present during the arrangement:
A48: Name: | R48: Relationship:
A50: Street Address: | R50: Phone # :
A52: City: | O52: State: | X52: Zip Code:
A53: Email address:
A55: Name: | R55: Relationship:
A57: Street Address: | R57: Phone # :
A59: City: | O59: State: | W59: Zip Code:
A60: Email address:
A62: Name: | R62: Relationship:
A64: Street Address: | R64: Phone # :
A66: City: | O66: State: | W66: Zip Code:
A67: Email address:
A69: Name: | R69: Relationship:
A71: Street Address: | R71: Phone # :
A73: City: | O73: State: | W73: Zip Code:
A74: Email address:
A76: Introduced Survey? | O76: Pathways Newsletter?
A77: FD: | F77: FSD: | O77: If yes, who to receive:

Sheet Cemetery Contract
U2: Washington Memorial Park & Mortuary
U3: 16445 International Boulevard
U4: SeaTac, WA 98188
U5: 206-242-1787
A7: STATEMENT OF CEMETERY INTERMENT RIGHTS, GOODS AND SERVICES
A12: Charges are only for those items that you selected or that are required. If we are required by law or by a cemetery or crematory to use any items, we will explain the reasons in writing below.
A15: Cemetery Services for: | G15: =Information!E6 -> 0 | K15: =Information!L6 -> 0 | O15: =Information!R6 -> 0 | T15: Date: | U15: =Information!X8 -> 0
A17: IF ITEMS BEING DELIVERED ARE ON AN EXISTING RETAIL INSTALLMENT CONTRACT ("RIC"), ENTER "ON CONTRACT" THEN REFERENCE CONTRACT NUMBER AND ANY BALANCE
A19: A. | B19: CEMETERY SERVICES Enter X in appropriate box | M19: PAYMENT
C20: 1st Right of Interment | M20: The purchaser agrees to pay cash which is understood to mean:
C21: Addl Right of Interment
B22: Location | D22: =Information!G42 -> 0 | I22: N/A | N22: Payment of the Total Cash Sales Prices upon execution of this contract.
B23: Endowment Care (ECF) | I23: N/A
D24: Total Right of Interment | K24: =SUM(I22:I23) -> 0 | N24: Payment of the Total Cash Sales Price in one installment on or before
B25: Recording Fee | I25: N/A | R25: Date:
B26: Opening and Closing | I26: N/A
B27: Other | I27: N/A
B28: Other | I28: N/A | N28: Payment of the Down-Payment upon execution of this contract and
B29: Service Friday thru Sunday or after 3:00 p.m. | I29: N/A | N29: payment of the unpaid balance in one installment on
R30: Date:
B31: RIC Contract # and Balance
B33: TOTAL CEMETERY SERVICES | K33: =SUM(K24)+SUM(I25:I29)+K31 -> 0
M34: Purchaser
B36: CEMETERY MERCHANDISE
A37: B. | B37: Container/Vault | I37: N/A | M37: Purchaser Signature
B38: Container / Vault Setting Fee | I38: N/A | M38: =Information!E15 -> 0 | W38: =Information!V15 -> 0
B39: Memorial | I39: N/A | M39: Purchaser Printed Name | V39: Relationship
B40: Memorial Base | I40: N/A | M40: =Information!F17 -> 0
B41: Installation | I41: N/A | M41: Address
B42: Vase / Base | I42: N/A | M42: =Information!U17 -> 0 | U42: =Information!C19 -> 0 | W42: =Information!J19 -> 0
B43: Vase / Base Setting Fee | I43: N/A | M43: City | U43: State | W43: Zip Code
B44: Urn | I44: N/A | M44: =Information!T21 -> 0 | V44: =Information!E21 -> 0
B45: Other | I45: N/A | M45: E-Mail Address | V45: Cell Phone Number
B46: Other | I46: N/A | M46: Co-Purchaser
B47: Sales Tax | E47: 0.104 | I47: =SUM(I37:I46)*E47 -> 0
B48: TOTAL CEMETERY MERCHANDISE | K48: =SUM(I37:I47) -> 0
M49: Purchaser Signature
B50: TOTAL CEMETERY CHARGES (A + B) | K50: =SUM(K33+K48) -> 0 | M50: =Information!E25 -> 0 | W50: =Information!V25 -> 0
M51: Co-Purchaser Printed Name | V51: Relationship
M52: =Information!F27 -> 0
...

Sheet Addendum A
U2: Washington Memorial Park & Mortuary
U3: 16445 International Boulevard
U4: SeaTac, WA 98188
U5: 206-242-1787
A7: STATEMENT OF CEMETERY INTERMENT RIGHTS, GOODS AND SERVICES
A12: Charges are only for those items that you selected or that are required. If we are required by law or by a cemetery or crematory to use any items, we will explain the reasons in writing below.
U14: ADDENDUM A
A15: Cemetery Services for: | G15: =Information!E6 -> 0 | K15: =Information!L6 -> 0 | O15: =Information!R6 -> 0 | T15: Date:
A17: IF ITEMS BEING DELIVERED ARE ON AN EXISTING RETAIL INSTALLMENT CONTRACT ("RIC"), ENTER "ON CONTRACT" THEN REFERENCE CONTRACT NUMBER AND ANY BALANCE
A19: A. | B19: CEMETERY SERVICES Enter X in appropriate box | M19: PAYMENT
C20: 1st Right of Interment | M20: The purchaser agrees to pay cash which is understood to mean:
C21: Addl Right of Interment
B22: Location | D22: =Information!G42 -> 0 | I22: N/A | N22: Payment of the Total Cash Sales Prices upon execution of this contract.
B23: Endowment Care (ECF) | I23: N/A
D24: Total Right of Interment | K24: =SUM(I22:I23) -> 0 | N24: Payment of the Total Cash Sales Price in one installment on or before
B25: Recording Fee | I25: N/A | R25: Date:
B26: Opening and Closing | I26: N/A
B27: Other | I27: N/A
B28: Other | I28: N/A | N28: Payment of the Down-Payment upon execution of this contract and
B29: Service Friday thru Sunday or after 3:00 p.m. | I29: N/A | N29: payment of the unpaid balance in one installment on
R30: Date:
B31: RIC Contract # and Balance
B33: TOTAL CEMETERY SERVICES | K33: =SUM(K24)+SUM(I25:I29)+K31 -> 0
M34: Purchaser
B36: CEMETERY MERCHANDISE
A37: B. | B37: Container/Vault | I37: N/A | M37: Purchaser Signature
B38: Container / Vault Setting Fee | I38: N/A | M38: =Information!E15 -> 0 | W38: =Information!V15 -> 0
B39: Memorial | I39: N/A | M39: Purchaser Printed Name | V39: Relationship
B40: Memorial Base | I40: N/A | M40: =Information!F17 -> 0
B41: Installation | I41: N/A | M41: Address
B42: Vase / Base | I42: N/A | M42: =Information!U17 -> 0 | U42: =Information!C19 -> 0 | W42: =Information!J19 -> 0
B43: Vase / Base Setting Fee | I43: N/A | M43: City | U43: State | W43: Zip Code
B44: Urn | I44: N/A | M44: =Information!T21 -> 0 | V44: =Information!E21 -> 0
B45: Other | I45: N/A | M45: E-Mail Address | V45: Cell Phone Number
B46: Other | I46: N/A | M46: Co-Purchaser
B47: Sales Tax | E47: ='Cemetery Contract'!E47 -> 0.104 | I47: =SUM(I37:I46)*E47 -> 0
B48: TOTAL CEMETERY MERCHANDISE | K48: =SUM(I37:I47) -> 0
M49: Purchaser Signature
B50: TOTAL CEMETERY CHARGES (A + B) | K50: =SUM(K33+K48) -> 0 | M50: ='Cemetery Contract'!M50 -> 0 | W50: ='Cemetery Contract'!W50 -> 0
M51: Co-Purchaser Printed Name | V51: Relationship
...

Sheet Addendum B
U2: Washington Memorial Park & Mortuary
U3: 16445 International Boulevard
U4: SeaTac, WA 98188
U5: 206-242-1787
A7: STATEMENT OF CEMETERY INTERMENT RIGHTS, GOODS AND SERVICES
A12: Charges are only for those items that you selected or that are required. If we are required by law or by a cemetery or crematory to use any items, we will explain the reasons in writing below.
U14: ADDENDUM B
A15: Cemetery Services for: | G15: =Information!E6 -> 0 | K15: =Information!L6 -> 0 | O15: =Information!R6 -> 0 | T15: Date:
A17: IF ITEMS BEING DELIVERED ARE ON AN EXISTING RETAIL INSTALLMENT CONTRACT ("RIC"), ENTER "ON CONTRACT" THEN REFERENCE CONTRACT NUMBER AND ANY BALANCE
A19: A. | B19: CEMETERY SERVICES Enter X in appropriate box | M19: PAYMENT
C20: 1st Right of Interment | M20: The purchaser agrees to pay cash which is understood to mean:
C21: Addl Right of Interment
B22: Location | D22: =Information!G42 -> 0 | I22: N/A | N22: Payment of the Total Cash Sales Prices upon execution of this contract.
B23: Endowment Care (ECF) | I23: N/A
D24: Total Right of Interment | K24: =SUM(I22:I23) -> 0 | N24: Payment of the Total Cash Sales Price in one installment on or before
B25: Recording Fee | I25: N/A | R25: Date:
B26: Opening and Closing | I26: N/A
B27: Other | I27: N/A
B28: Other | I28: N/A | N28: Payment of the Down-Payment upon execution of this contract and
B29: Service Friday thru Sunday or after 3:00 p.m. | I29: N/A | N29: payment of the unpaid balance in one installment on
R30: Date:
B31: RIC Contract # and Balance
B33: TOTAL CEMETERY SERVICES | K33: =SUM(K24)+SUM(I25:I29)+K31 -> 0
M34: Purchaser
B36: CEMETERY MERCHANDISE
A37: B. | B37: Container/Vault | I37: N/A | M37: Purchaser Signature
B38: Container / Vault Setting Fee | I38: N/A | M38: =Information!E15 -> 0 | W38: =Information!V15 -> 0
B39: Memorial | I39: N/A | M39: Purchaser Printed Name | V39: Relationship
B40: Memorial Base | I40: N/A | M40: =Information!F17 -> 0
B41: Installation | I41: N/A | M41: Address
B42: Vase / Base | I42: N/A | M42: =Information!U17 -> 0 | U42: =Information!C19 -> 0 | W42: =Information!J19 -> 0
B43: Vase / Base Setting Fee | I43: N/A | M43: City | U43: State | W43: Zip Code
B44: Urn | I44: N/A | M44: =Information!T21 -> 0 | V44: =Information!E21 -> 0
B45: Other | I45: N/A | M45: E-Mail Address | V45: Cell Phone Number
B46: Other | I46: N/A | M46: Co-Purchaser
B47: Sales Tax | E47: ='Cemetery Contract'!E47 -> 0.104 | I47: =SUM(I37:I46)*E47 -> 0
B48: TOTAL CEMETERY MERCHANDISE | K48: =SUM(I37:I47) -> 0
M49: Purchaser Signature
B50: TOTAL CEMETERY CHARGES (A + B) | K50: =SUM(K33+K48) -> 0 | M50: ='Cemetery Contract'!M50 -> 0 | W50: ='Cemetery Contract'!W50 -> 0
M51: Co-Purchaser Printed Name | V51: Relationship
...

Sheet Deed Transfer Contract
U2: Washington Memorial Park & Mortuary
U3: 16445 International Boulevard
U4: SeaTac, WA 98188
U5: 206-242-1787
A7: STATEMENT OF CEMETERY INTERMENT RIGHTS, GOODS AND SERVICES
A12: Charges are only for those items that you selected or that are required. If we are required by law or by a cemetery or crematory to use any items, we will explain the reasons in writing below.
A15: Cemetery Services for: | G15: =Information!E6 -> 0 | K15: =Information!L6 -> 0 | O15: =Information!R6 -> 0 | T15: Date: | U15: =Information!X8 -> 0
A17: IF ITEMS BEING DELIVERED ARE ON AN EXISTING RETAIL INSTALLMENT CONTRACT ("RIC"), ENTER "ON CONTRACT" THEN REFERENCE CONTRACT NUMBER AND ANY BALANCE
A19: A. | B19: CEMETERY SERVICES Enter X in appropriate box | M19: PAYMENT
C20: 1st Right of Interment | M20: The purchaser agrees to pay cash which is understood to mean:
C21: Addl Right of Interment
B22: Location | D22: =Information!G42 -> 0 | I22: N/A | N22: Payment of the Total Cash Sales Prices upon execution of this contract.
B23: Endowment Care (ECF) | I23: N/A
D24: Total Right of Interment | K24: =SUM(I22:I23) -> 0 | N24: Payment of the Total Cash Sales Price in one installment on or before
B25: Recording Fee | I25: N/A | R25: Date:
B26: Opening and Closing | I26: N/A
B27: Deed Transfer Fee | I27: N/A
B28: Other | I28: N/A | N28: Payment of the Down-Payment upon execution of this contract and
B29: Service Friday thru Sunday or after 3:00 p.m. | I29: N/A | N29: payment of the unpaid balance in one installment on
R30: Date:
B31: RIC Contract # and Balance
B33: TOTAL CEMETERY SERVICES | K33: =SUM(K24)+SUM(I25:I29)+K31 -> 0
M34: New Interment Right Owner
B36: CEMETERY MERCHANDISE
A37: B. | B37: Container/Vault | I37: N/A | M37: Grantee Signature
B38: Container / Vault Setting Fee | I38: N/A
B39: Memorial | I39: N/A | M39: Interment Right Grantee Printed Name
B40: Memorial Base | I40: N/A
B41: Installation | I41: N/A | M41: Address
B42: Vase / Base | I42: N/A
B43: Vase / Base Setting Fee | I43: N/A | M43: City | U43: State | W43: Zip Code
B44: Urn | I44: N/A
B45: Other | I45: N/A | M45: E-Mail Address | V45: Cell Phone Number
B46: Other | I46: N/A | M46: Current Interment Right Owner
B47: Sales Tax | E47: 0.104 | I47: =SUM(I37:I46)*E47 -> 0
B48: TOTAL CEMETERY MERCHANDISE | K48: =SUM(I37:I47) -> 0
M49: Grantor Signature
B50: TOTAL CEMETERY CHARGES (A + B) | K50: =SUM(K33+K48) -> 0
M51: Interment Right Grantor Printed Name
B53: TOTAL CASH SALES PRICE | K53: =K50 -> 0 | M53: Address
...

Sheet Payment Options
A5: Deceased: | C5: =CONCATENATE(Information!E6," ",Information!L6," ",Information!R6) | H5: Date of Service | J5: =Information!W12 -> 0
A7: PAYMENT OPTIONS
A9: 1. We are a family-owned business that treats every family we serve with dignity and respect. We are, however, dependent upon our client families for prompt payment and we request that payment be made prior to services. This applies to both cemetery and funeral agreements.
A11: Your estimated account balance in the amount of | H11: (excluding estimated amounts from
A12: un-contested pre-arranged funeral insurance and/or trust) may be settled with the following payment types and timeframes:
C14: 1. | D14: Checks*: | F14: 5 Banking Days
C15: 2. | D15: Credit Cards: | F15: 3 Business Days
C16: 3. | D16: Cashier's Checks: | F16: 2 Business Days
C17: 4. | D17: Cash [1] | F17: 2 Business Days
B19: We cannot accept checks written on the deceased’s checking account unless you are a joint account holder. We cannot accept payment with a credit card in the deceased’s name. In cases where the deceased’s estate must pay the funeral expenses, we ask that the family representative(s) pay the funeral and/or cemetery expenses and file a claim for reimbursement with the deceased’s estate.
B21: [1] In accordance with IRS requirements, cash payments in excel of $10,000 will require the completion of IRS Form 8300 “Report of Cash Payments Over $10,000 Received in Trade or Business” including identifying documents.
A23: Exceptions to payment requirements:
A25: a. Pre-paid Funeral Insurance or Trust Policies
A26: i. Policy must be taken out more than two years prior to death (non-contestable policies).
A27: ii. Any estimated additional balance due must be paid in the manner and timeframe noted above.
A28: b. Acceptance of a third-party life insurance assignment
A29: i. Policy must be taken out more than two years prior to death (non-contestable policies)
A30: ii. Any estimated additional balance due must be paid in the manner and timeframe noted above.
A31: iii. There is a 3.5% fee for processing of a third-party life insurance assignment.
A33: 2. Third-party Items – Payment for death certificates, cemetery merchandise, clergy, church, organist, escorts, airfare, flowers, limos, or other third-party (cash advance) items is required before these items can be coordinated or ordered. To avoid delays, it is recommended to plan or order these items sooner than the payment requirements above.
A35: The cost of your third-party items are:
B38: PRIMARY PURCHASER | H38: CO-PURCHASER
B42: Signature | H42: Signature
B44: =CONCATENATE(Information!E15," ",Information!V15) | H44: ='Cemetery Contract'!M50 -> 0
B45: Printed Name/Relationship | H45: Printed Name/Relationship
B48: Date | H48: Date

Sheet Mem Order Flat Mrkr & Bronze
G1: MEMORIAL ORDER FORM
F4: INTERNAL USE ONLY | L4: NOTE THAT THIS FORM IS INTENDED TO PRINT AND COMPLETE. CERTAIN FIELDS ARE SELF POPULATING OR ALLOW ENTRY
F5: Date Ordered _____________________ | I5: Vendor Order Confirmation | L5: BLUE FIELDS ARE SELF POPULATING FROM THE INFORMATION TAB
A6: 16445 International Blvd., SeaTac, WA 98188 206-242-1787 | www.bonneywatson.com | F6: Paid Date _________________________ | I6: Date: ____________________________ | L6: GREEN FIELDS CAN HAVE ENTRIES TYPED BEFORE PRINTING. | R6: )
F7: Indicate if Financing & Expected Payoff | I7: Bronze SO #________________________
F8: Contract # | G8: =IF(Information!F3="","",Information!F3) | I8: Granite SO #________________________
A9: Date: | F9: ORDER TYPE: ORDER STATUS: (Must be paid in full to order now)
A10: For: | B10: =CONCATENATE(Information!E6," ",Information!L6," ",Information!R6) | F10: Sketch
A11: Manufacturer
A12: Monument Type:
A13: Granite Color
A14: Granite Flat Marker Size
A15: Bronze Marker Size
A16: Foundation Size
A17: Design No. | F17: Inscription
A18: Lettering Font Style
A19: Emblem(s)
A20: Portrait
A21: Vase Option
A22: Vase Type | F22: Special Instructions
A24: Property Location:
B25: =Information!G42 -> 0
A26: Family Service Director | C26: =Information!Y6 -> 0
F27: Installation Instructions
A32: The undersigned hereby certifies and represents that they are the owner(s) or the authorized representative(s) of the owner(s) of the above-described Interment Rights and hereby authorize placement of memorialization for the named deceased on the interment space. Upon approval of the memorial design and lettering, Cemetery is hereby authorized to install the completed memorial items on the interment space. The undersigned hereby agree to indemnify and hold harmless the cemetery, its agents, and employees from all liability, including reasonable attorney's fees, and against any loss it or any of them may sustain in connection with installation of memorialization authorized hereunder. Further, the undersigned agree that the cemetery shall have the right to correct any error in the memorialization at its own expense, without any liability for such error. If placing memorial prior to death or interment, I understand additional fees may apply for final inscription and/or date scroll. I have checked the above inscription and found the dates and spelling correct. I understand that the above purchase will not be ordered until the funeral and cemetery accounts are paid in full and final proof is approved. I understand that four proofs are included. There will be a charge of $165 for each additional proof. Estimated granite memorial arrival time is up to weeks from approval of final proof. Estimated bronze memorial arrival time is up to weeks from approval of final proof. Estimated VA marker arrival time is 6 - 12 months. I understand that if this order is cancelled after proofs have been provided, there will be a $295 proof fee.
A43: Number of Signatures Required | F43: (Additional Signature section on next page)
K45: Contact for Design Approval
K46: FALSE
A47: SIGNATURE: Interment Right Owner or Authorized Representative | I47: DATE
A49: =IF([1]Information!E15="","",[1]Information!E15)
A50: PRINTED NAME: Interment Right Owner | F50: RELATIONSHIP of Authorized Representative to Interment Right Owner
A51: =IF([1]Information!T21="","",[1]Information!T21)
A52: PHONE NUMBER: Interment Right Owner/Authorized Representative
A53: =IF([1]Information!Y6="","",[1]Information!Y6)
A54: EMAIL ADDRESS: Interment Right Owner/Authorized Representative

Sheet Mem Order Form Upright & Other
G1: MEMORIAL ORDER FORM
F3: INTERNAL USE ONLY
F4: Contract # | G4: =IF(Information!F3="","",Information!F3) | L4: NOTE THAT THIS FORM IS INTENDED TO PRINT AND COMPLETE. CERTAIN FIELDS ARE SELF POPULATING OR ALLOW ENTRY
F5: Date Ordered _____________________ | I5: Vendor Order Confirmation | L5: BLUE FIELDS ARE SELF POPULATING FROM THE INFORMATION TAB
A6: 16445 International Blvd., SeaTac, WA 98188 206-242-1787 | www.bonneywatson.com | F6: Paid Date _________________________ | I6: Date: __________________ Granite SO #________________ | L6: GREEN FIELDS CAN HAVE ENTRIES TYPED BEFORE PRINTING.
F7: Indicate if Financing & Expected Payoff
A9: Date: | F9: ORDER TYPE: ORDER STATUS: (Must be paid in full to order now)
A10: For: | B10: =CONCATENATE(Information!E6," ",Information!L6," ",Information!R6) | F10: Sketch
A11: Manufacturer
A12: Monument Type:
A13: Granite Color
A14: Upright Size
A15: Custom Size
A16: Upright Tablet Shape
A17: Upright Tablet Finish
A18: Custom Finish
A19: Upright Base Finish
A20: Bevel/Margin
A21: Upright Foundation Size
A22: Bench Size and Style
A23: Design No. | F23: Inscription
A24: Lettering Font Style
A25: Emblem(s)
A26: Portrait
A27: Vase Option
A28: Vase Type
A29: Installation Instructions | F29: Special Instructions
A33: Property Location: | C33: =Information!G42 -> 0 | H33: Family Service Director | J33: =Information!Y6 -> 0
A35: The undersigned hereby certifies and represents that they are the owner(s) or the authorized representative(s) of the owner(s) of the above-described Interment Rights and hereby authorize placement of memorialization for the named deceased on the interment space. Upon approval of the memorial design and lettering, Cemetery is hereby authorized to install the completed memorial items on the interment space. The undersigned hereby agree to indemnify and hold harmless the cemetery, its agents, and employees from all liability, including reasonable attorney's fees, and against any loss it or any of them may sustain in connection with installation of memorialization authorized hereunder. Further, the undersigned agree that the cemetery shall have the right to correct any error in the memorialization at its own expense, without any liability for such error. If placing memorial prior to death or interment, I understand additional fees may apply for final inscription and/or date scroll. I have checked the above inscription and found the dates and spelling correct. I understand that the above purchase will not be ordered until the funeral and cemetery accounts are paid in full and final proof is approved. I understand that four proofs are included. There will be a charge of $165 for each additional proof. Estimated granite memorial arrival time is up to weeks from approval of final proof. I understand that if this order is cancelled after proofs have been provided, there will be a $295 proof fee.
A44: Number of Signatures Required | F44: (Additional Signature section on next page)
K46: Contact for Design Approval
K47: FALSE
A48: SIGNATURE: Interment Right Owner or Authorized Representative | I48: DATE
A50: =IF([1]Information!E15="","",[1]Information!E15)
A51: PRINTED NAME: Interment Right Owner | F51: RELATIONSHIP of Authorized Representative to Interment Right Owner
A52: =IF([1]Information!T21="","",[1]Information!T21)
A53: PHONE NUMBER: Interment Right Owner/Authorized Representative | F53: EMAIL ADDRESS: Interment Right Owner/Authorized Representative

Sheet Mem Order Form Addl Signers
N2: MEMORIAL ORDER FORM
O3: Name of Decedent: | P3: =CONCATENATE(Information!E6," ",Information!L6," ",Information!R6) | U3: This field will populate from the Information tab
A5: ADDITIONAL SIGNATURES
A7: SIGNATURE #2
A8: Signature | U8: Contact for Design Approval
B9: Interment Right Owner or Authorized Representative | Q9: Date | U9: FALSE
B11: Printed Name | O11: Relationship
A12: Email Address
A13: FALSE | B13: Please send me a copy of the memorial design for informational purposes only. I understand memorial design approval will be authorized by individual named herein.
A15: SIGNATURE #3
A16: Signature | U16: Contact for Design Approval
B17: Interment Right Owner or Authorized Representative | Q17: Date | U17: FALSE
B19: Printed Name | O19: Relationship
A20: Email Address
A21: FALSE | B21: Please send me a copy of the memorial design for informational purposes only. I understand memorial design approval will be authorized by individual named herein.
A23: SIGNATURE #4
A24: Signature | U24: Contact for Design Approval
B25: Interment Right Owner or Authorized Representative | Q25: Date | U25: FALSE
B27: Printed Name | O27: Relationship
A28: Email Address
A29: FALSE | B29: Please send me a copy of the memorial design for informational purposes only. I understand memorial design approval will be authorized by individual named herein.
A31: SIGNATURE #5
A32: Signature | U32: Contact for Design Approval
B33: Interment Right Owner or Authorized Representative | Q33: Date | U33: FALSE
B35: Printed Name | O35: Relationship
A36: Email Address
A37: FALSE | B37: Please send me a copy of the memorial design for informational purposes only. I understand memorial design approval will be authorized by individual named herein.
A39: SIGNATURE #6
A40: Signature | U40: Contact for Design Approval
B41: Interment Right Owner or Authorized Representative | Q41: Date | U41: FALSE
B43: Printed Name | O43: Relationship
A44: Email Address
A45: FALSE | B45: Please send me a copy of the memorial design for informational purposes only. I understand memorial design approval will be authorized by individual named herein.

Sheet FTC disclosure form
A1: BONNEY-WATSON FUNERAL HOMES
E4: BONNEY-WATSON | I4: BONNEY-WATSON | M4: BONNEY-WATSON | R4: WIGGEN & SONS | W4: SOUTHWEST
E5: Capitol Hill | I5: Washington Memorial | M5: Federal Way | R5: Ballard | W5: MORTUARY
E6: 1732 Broadway | I6: 16445 Int'l. Blvd. | M6: 1535 S.W. Dash Pt. Rd. | R6: C/O 1732 Broadway | W6: 9021 Rainier Avenue S
E7: Seattle, WA 98122 | I7: SeaTac, WA 98188 | M7: Federal Way, WA 98023 | R7: Seattle, WA 98122 | W7: Seattle, WA 98118
E8: 2063220013 | I8: 2062421787 | M8: 2538397317 | R8: (206) 782-4700 | W8: (206) 722-3675
A11: FTC DISCLOSURE / DISCLAIMER FORM
B14: The Federal Trade Commission's Funeral Industry Practices Rule requires certain disclosures and prohibits misrepresentations. This Disclosure / Disclaimer Form is a checklist we ask those we serve to read and sign if during the funeral arrangements our firm complied with the following:
B20: NAME OF DECEASED:
B23: DATE OF DEATH:
B26: 1. The undersigned received a General Price List effective on November 4, 2015 prior to discussing prices, arrangements, services or merchandise. 2. The undersigned received a Casket Price List effective on January 28, 2016 prior to viewing or discussing prices of caskets. 3. The undersigned received an Outer Burial Container Price List effective on February 11, 2015 prior to viewing or discussing prices of outer burial containers. 4. The undersigned were told that embalming is not required by law except in certain cases. 5. If embalming was provided, it was done with the permission of the undersigned. The undersigned were told that the law does not require embalming for direct cremation, immediate burial or if refrigeration is selected. 6. The undersigned were informed that the law does not require a casket for direct cremation. 7. The undersigned were informed that the law does not require the purchase of an outer burial container. 8. The funeral home made no representations to the undersigned that embalming or the use of any merchandise available from the funeral home would delay the decomposition of the deceased for a long time or indefinite time. 9. The undersigned understands that the funeral home as disclaimed all warranties with regard to caskets, outer burial containers and other merchandise sold by the funeral home. The undersigned further understands that the only warranties, expressed or implied, granted in connection with the manufacturers of the goods sold by the funeral home are the express written warranties, if any, which are extended by the manufacturers of the goods. No other warranties, including the implied warranties of merchantability or fitness for a particular purpose are extended by the funeral home. 10. Bonney-Watson Funeral Homes/Southwest Mortuary limousines will accommodate seven people plus our driver. Children who are required by law to be in car seats must comply.
W56: INITIAL: __________________
E59: (Signature)
E63: (Relationship)
E67: (Date) | AL67: =(10995)*1 -> 10995

Sheet Old Choices Related to payment 
A1: CHOICES RELATED TO PAYMENT
A3: 1. Third Party Items – Payment for cemetery, clergy, church, organist, or other third party items is required before the funeral service because each of these requires payment when their service is provided. Your total for Third Party Items is $
A5: Your total for Third Party Items is | G5: and must be paid prior to services.
A7: 2. Funeral Account – We are a family-owned business that treats every family we serve with dignity and respect. We are, however, dependent upon our client families for prompt payment and we request that payment be made prior to services.
A11: Your Funeral Home Account in the amount of $ | H11: may be settled as follows:
B13: A. This is a cash transaction. Payment may be made in cash, personal check, bank check, money order, Visa, MasterCard, Discover or American Express.
B16: B. In cases where the deceased’s estate must pay the funeral expenses, we ask that family representative(s) pay the funeral expenses and file claim for reimbursement with the deceased’s estate.
B20: C. In some cases, payment can be made by the acceptance of an insurance assignment by a third-party vendor. There is a 3.5% fee for third-party insurance assignments ($150.00 minimum)
A23: Payment is expected at the time arrangements are made with the funeral home
A25: Financial responsibility must be mutually agreed upon by at least one family representative and Bonney-Watson Funeral Home. This signed agreement represents your understanding of the payment policy of Bonney-Watson Funeral Home.
A29: You agree to settle the funeral account for the services of:
A30: =Information!E6 -> 0 | D30: =Information!L6 -> 0 | G30: =Information!R6 -> 0
A31: in the following manner:
A37: FAMILY REPRESENTATIVE | G37: FUNERAL HOME REPRESENTATIVE
A39: S.S. #
H40: DATE
B42: DATE
A45: FAMILY REPRESENTATIVE
A47: S.S. #
B50: DATE

Sheet INTERMENT AUTH NEW
O1: INTERMENT ORDER AND AUTHORIZATION
A3: Authorization is hereby given to WASHINGTON MEMORIAL PARK & MORTUARY, INC., subject to their rules, conditions, and regulations to inter the remains of:
A5: Name of Decedent: | D5: =CONCATENATE(Information!E6," ",Information!L6," ",Information!R6) | P5: VETERAN?
C7: Date of Birth: | F7: =Information!F8 -> 0 | L7: Date of Death: | O7: =Information!F10 -> 0 | R7: =Information!L8 -> Age: 0 Years 0 Months
A10: SERVICE INFORMATION
A12: Funeral Date: | C12: =Information!W10 -> 0 | I12: Time: | K12: =Information!AC10 -> 0 | N12: Funeral Director: | R12: =Information!F12 -> 0
A14: Funeral Home: | C14: =Information!X3 -> 0
A16: Interment Date: | C16: =Information!W12 -> 0 | I16: Time: | K16: =Information!AC12 -> 0 | M16: Family Service Director: | R16: =Information!Y6 -> 0
A18: Service Type: | K18: Service Coming From:
A21: CEMETERY INFORMATION
A23: Cemetery Interment Right, Goods & Services CONTRACT #: | O23: CONTRACT PAID IN FULL DATE:
A25: Contract must be paid in full prior to IOA Processing
B27: Interment Space | F27: =Information!G42 -> 0 | O27: Interment Type
B29: 1st Right | G29: Addl Right | L29: Double Depth | O29: Oversize: | Q29: [Oversize Placement requires Approval below]
A31: VAULT DESCRIPTION | D31: =Information!X42 -> 0 | P31: EMBLEM
C33: WITNESS LOWERING: | M33: NON-WITNESS LOWERING:
A35: FOR CREMATION ONLY (if Family will bring Cremated Remains)
A37: STATUS OF CREMATED REMAINS:
A39: TYPE OF URN | L39: SIZE OF URN (H x W x L):
A42: DELIVERY OF PRE-ARRANGED MERCHANDISE & SERVICES
A44: Pre-Arrangement Contract # | I44: Amount Owed: | P44: Date Payment Received
C47: Container/Vault | I47: Opening & Closing | P47: Recording Fee
C49: Container/Vault Setting Fee | J49: Memorial and Setting Fee
C51: Vase / Base / Setting Fee | P51: Urn
C53: Other Merchandise (i.e. Inscription)
A55: ADDITIONAL REMARKS:
O59: INTERMENT ORDER AND AUTHORIZATION
O60: Name of Decedent: | P60: =CONCATENATE(Information!E6," ",Information!L6," ",Information!R6) | V60: This field will populate from the Information tab
U61: Page 2 of 2
A63: The undersigned hereby certify that they are the person(s) with the right to control disposition of the named deceased and authorize the above-named cemetery to make disposition of the remains of the deceased as indicated above. The undersigned hereby further certify and represent that they are the owner(s) or the authorized representative(s) of the owner(s) of the above-described Interment Rights and hereby authorize use of said Interment Rights for the interment, entombment, or inurnment of the remains of the herein named deceased. Cemetery is hereby authorized to install any outer burial container purchased in connection with this interment described herein. The undersigned hereby agree to indemnify and hold harmless the cemetery, its agents, and employees from all liability, including reasonable attorney's fees, and against any loss it or any of them may sustain in connection with the interment, entombment, or inurnment authorized hereunder. Further, the undersigned agree that the cemetery shall have the right to correct any error in the interment, at its own expense, without any liability for such error.
B65: Number of Signatures required: | L65: (Additional Signature section on next page)
A67: Signature
B68: Interment Right Owner or Authorized Representative | R68: Date
B70: Printed Name | O70: Relationship
A71: Address
B72: Street Address City State Zip | R72: Phone Number
A75: Family Location Verification:
A76: Interment Space: | E76: =Information!G42 -> 0 | V76: This field will populate from the Information tab
A78: Interment right Owner or Authorized Representative Printed Name
A81: IF DIFFERENT FROM AUTHORIZED REPRESENTATIVE:
...

Sheet IOA ADDL SIGNERS
N2: INTERMENT ORDER AND AUTHORIZATION
O3: Name of Decedent: | P3: =CONCATENATE(Information!E6," ",Information!L6," ",Information!R6) | U3: This field will populate from the Information tab
A5: ADDITIONAL SIGNATURES
A7: SIGNATURE #2
A8: Signature
B9: Interment Right Owner or Authorized Representative | Q9: Date
B11: Printed Name | O11: Relationship
A12: Address
B13: Street Address City State Zip | Q13: Phone Number
A15: SIGNATURE #3
A16: Signature
B17: Interment Right Owner or Authorized Representative | Q17: Date
B19: Printed Name | O19: Relationship
A20: Address
B21: Street Address City State Zip | Q21: Phone Number
A23: SIGNATURE #4
A24: Signature
B25: Interment Right Owner or Authorized Representative | Q25: Date
B27: Printed Name | O27: Relationship
A28: Address
B29: Street Address City State Zip | Q29: Phone Number
A31: SIGNATURE #5
A32: Signature
B33: Interment Right Owner or Authorized Representative | Q33: Date
B35: Printed Name | O35: Relationship
A36: Address
B37: Street Address City State Zip | Q37: Phone Number
A39: SIGNATURE #6
A40: Signature
B41: Interment Right Owner or Authorized Representative | Q41: Date
B43: Printed Name | O43: Relationship
A44: Address
B45: Street Address City State Zip | Q45: Phone Number

Sheet Life's Reflections Order Form

Sheet BLIND CHECK
Z1: Date Blind Check Submitted:
A3: BLIND CHECK
A5: Deceased: | L5: =CONCATENATE(Information!E6," ",Information!L6," ",Information!R6)
A7: GARDEN: | L7: =IF(Information!G42="","",VLOOKUP(LEFT(Information!G42,FIND("-",Information!G42)-1),'GARDENS ETC.'!A1:B57,2,FALSE))
A9: SPACE LOCATION
O10: To be compled by Family Service Director
A11: Graveside Service Date: | U11: =Information!W12 -> 0 | Z11: Time: | AB11: =Information!AC12 -> 0
A13: Family Service Director: | Q13: =Information!Y6 -> 0 | AA13: Date:
A15: Lawn Interment Map | Z15: Niche/Crypt
A16: 4 | D16: 3 | G16: 2 | J16: 1 | M16: 4 | P16: 3 | S16: 2 | V16: 1
F17: C | R17: B
F21: D | R21: A
A23: 4 | D23: 3 | G23: 2 | J23: 1 | M23: 4 | P23: 3 | S23: 2 | V23: 1
C26: Location verified against:
F28: Cemetery Records
F30: IOA
A33: Vault/Liner Indicated on Flag:
A35: Blind Check Completed by:
A38: Date: | Y38: Time:

Sheet Disinterment Order and Auth
A1: DISINTERMENT ORDER AND AUTHORIZATION
A3: TO: WASHINGTON MEMORIAL PARK | BZ3: Date: | CI3: X | GT3: Cross | GU3: Full Service (F.S.) | GV3: Monticello | GW3: Monday | GX3: Husband | GY3: Lawn Interment | GZ3: Standard Concrete | HA3: Granite
A4: Subject to your rules, conditions and regulations, you are hereby authorized to disinter the remains of | GT4: Crucifix | GU4: Full Service Graveside (FSG) | GV4: Gold | GW4: Tuesday | GX4: Wife | GY4: Mausoleum Entombment | GZ4: Monticello | HA4: Bronze
A5: NAME OF DECEDENT: | Y5: =Information!E6 -> 0 | AT5: =Information!$L$6 -> 0 | BM5: =Information!$R$6 -> 0 | CK5: Veteran? | CW5: Yes | DE5: No | GT5: Russian Orthodox Cross | GU5: Full Service Crypt (FSC) | GV5: Continental | GW5: Wednesday | GX5: Son | GY5: Lawn Crypt Interment | GZ5: Continental | HA5: Monobar
A7: Date of Birth: | O7: =Information!F8 -> 0 | AQ7: Date of Death: | BF7: =Information!F10 -> 0 | CK7: =#REF! -> #REF! | GT7: Dove of Peace | GU7: Full Service Niche (FSN) | GV7: Gold and Black | GW7: Thursday | GX7: Daughter | GY7: Niche Inurnment | GZ7: Venetian | HA7: Inscription
GT8: Star of David | GU8: Graveside Service (G.S.) | GV8: Veterans | GW8: Friday | GX8: Sister | GY8: Lawn Inurnment | GZ8: Cameo Rose | HA8: Staff Bar
A9: from the following interment space: | AI9: =Information!G42 -> 0 | CN9: =#REF! -> #REF! | GT9: Eagles | GU9: Graveside Service Lobby (GSL) | GV9: Grey and Blue | GW9: Saturday | GX9: Brother | GY9: Mausoleum Inurnment | GZ9: SST Triune | HA9: Bronze Plate
GT10: Praying Hands | GU10: Witness Cremation (WIT C) | GV10: Bronze Triune | GX10: Step Son | GZ10: Monarch
A11: Outer Burial Container: | X11: =Information!X42 -> 0 | BX11: Emblems: | CJ11: =#REF! -> #REF! | GT11: Independent Order of Odd Fellows | GU11: Witness Placement (WIT P) | GV11: Gold and Black | GX11: Step Daughter | GZ11: Pres Urn Vault Standard
GT12: US Air Force | GV12: Presidential Urn Vault | GX12: Great Grandmother
A13: Remarks:
GT14: US Marine Corps | GV14: Black | GX14: Great Grandfather
GT15: US Navy | GV15: Green | GX15: Guardian
GV16: Rose | GX16: Friend
GV17: White | GX17: None
A18: The undersigned hereby certify that they are the legal custodian(s) of the herein named deceased, having full legal authority to direct the disinterment, disentombment or disinurnment of the remains of the deceased, and authorize the above named cemetery to make disposition of the remains of the deceased as indicated above. The undersigned hereby further certify and represent that they are the owner(s) or the authorized representative(s) of the owner(s) of the above described Interment Rights and hereby authorize us to perform this disinterment. | GX18: Cousin
GX19: Grandson
A20: The undersigned hereby agree to indemnify and hold harmless the cemetery, its agents, and employees from any and all liability, including reasonable attorney's fees, and against any loss it or any of them may sustain in connection with the disinterment, disentombment or disinurnment authorized hereunder.
A22: Signature
K23: (Authorized Representative) | AZ23: Print Name | CL23: Relationship
A24: Address
J25: Street | AN25: City | BC25: State | BI25: Zip | BS25: Cell Phone | CL25: Email | GV25: Continental
A27: Signature: | GV27: Venetian
K28: (Authorized Representative) | AZ28: Print Name | CL28: Relationship
A29: Address
J30: Street | AN30: City | BC30: State | BI30: Zip | BS30: Cell Phone | CL30: Email | GV30: Continental
A31: Signature of Disinterment Right Owner:
AK32: (If different from authorized representative) | CD32: (Print Name)
A34: Family location verification:
AF35: Authorized Representative | CC35: (Print Name)
GV36: Wilbert Bronze
A37: OFFICE USE ONLY
A38: Superintendent's verification:
A39: Contract No.: | AZ39: Disinterment No.: | CI39: Date:
GV40: Pres Urn Vault Standard
GV42: Pres Urn Vault Oversize
B43: Notary Use:
GV44: Wilbert Triune Urn Vault
X45: State of Washington | BE45: )
BE46: ) | BH46: ss
...

Sheet Vault and Urn Vault Order Form
A10: VAULT AND URN VAULT ORDER FORM
A11: Washington Memorial Park
A12: 16445 International Blvd, SeaTac, Washington 98188
A13: Phone: 206-242-1787 Fax: 206-242-1791
A14: PLEASE PRINT CLEARLY
A17: Please SCAN / EMAIL your order as soon as the product has been sold to your customer so that we can get it on the deliver
A18: schedule right away. Thank you!
A21: Vault Type | I21: Color
C23: Is this an URN VAULT? | F23: If YES, please specify: | J23: 18" Tall
J25: 12" Tall (Monticello & Venetian only)
A27: Date of Service
B29: Time of Service | G29: Graveside | J29: Chapel/Church
B31: Name of Deceased
C32: (Please PRINT name clearly, exactly as you wish it to appear on name plate)
B34: Year of Birth | F34: Year of Death | J34: Emblem
B36: If selecting a personalization format such as Life's Reflections or a Legacy Print, please include a layout form.
B37: (Please note: These can only be applied to the Venetian or metal vaults and urn vaults.)
A40: Wilbert Preneed Certificate Number (if any)
A42: Name of person who sold vault for your company
A44: Confirmed with you by
A47: Signature of family member confirming spelling and dates for nameplate:
A49: Any additional information:
A56: orders@psprecast.com
A57: Wilbert will respond back with a Confirmation Email
A58: Phone: 253-531-2656

Sheet Cemetery Rules
B6: SUMMARY OF CEMETERY RULES & REGULATIONS
A9: Purchaser | C9: =Information!E15 -> 0
A11: Address | C11: =Information!F17 -> 0
A13: City | C13: =Information!U17 -> 0 | F13: State | H13: =Information!C19 -> 0 | I13: Zip | J13: =Information!J19 -> 0 | L13: Phone | M13: =Information!E21 -> 0
B15: These rules and regulations are designed to preserve the appearance and dignity of the garden and mausoleum areas at Washington Memorial Park & Mortuary, Inc. [“Cemetery Authority” or “park”]. They are intended to honor the lives of those memorialized here.
A17: GENERAL GUIDELINES
C19: Visiting hours for the cemetery grounds are:
D20: Cemetery Grounds: | H20: 8:30 until Dusk
D21: Mausoleum: | H21: 9:00 AM – 5:00 PM (Monday to Saturday)
H22: 10:00 AM – 3:00 PM (Sunday)
D23: Office Hours: | H23: 9:00 AM to 5:00 PM (Monday to Saturday)
H24: 10:00 AM to 4:00 PM (Sunday)
C26: Once a casket has been placed in a burial vault or other location, including on a casket lowering devise, within, or adjacent to an open grave, or on a cemetery church truck, the Cemetery Authority does not permit the casket to be opened, due to safety and privacy considerations of guest, staff, and decedent.
C28: Personal temporary enclosures/canopies/tents are not permitted.
C30: Food and/or alcohol are not permitted in the park.
C32: Personal vehicles should not impede road access. Park staff may require you to relocate your vehicle if it causes an
C33: obstruction.
C35: To respect the resting places of others, please refrain from obstructing adjacent graves when visiting your loved ones.
C37: Vehicles in the park shall observe a speed limit of 15 MPH.
C39: Keep purses and other valuables locked in your trunk.
C41: All trees, shrubs and plantings are the property of Washington Memorial Park & Mortuary, Inc. Plantings by individuals
C42: are not permitted.
C44: Pets are not allowed in the park except for trained guide dogs or when kept in automobiles.
C46: Funeral flowers will be removed when they become unsightly.
C48: All grave decorations will be removed and discarded 7-14 days after each holiday.
A50: MEMORIAL GARDENS
C52: Floral receptacles shall not be placed on any plot unless first approved by the cemetery authority and when placed,
C53: shall remain subject to the rules and regulations of the park.
C55: No enclosure of any kind shall be permitted around any plot or lot. The placing of articles such as balloons, pinwheels,
C56: planter boxes, souvenirs, photographs, glass, decorative rocks or preserved flowers is prohibited. Such items will be
C57: removed and disposed of by park personnel.
C59: Artificial flowers are only permitted during the non-mowing season. Any artificial flowers that are placed on graves
C60: during mowing season will be removed and disposed of by park personnel.
C62: Fresh cut flowers are allowed in the park at all times in regulation vases and will be removed and disposed of
C63: by park personnel when they become unsightly.
C65: Non-permanent vases are not allowed.
C67: Permanent vases are available for purchase through the office and will be installed by the park.
A69: MAUSOLEUMS AND COLUMBARIUMS
C71: Urns, inscriptions, name plates, fittings, and adornments for crypts or niches shall not be placed unless first approved by
C72: the cemetery authority. If permission is not received, they will be removed and disposed of by park personnel.
...

Sheet Hold Harmless Agreement
B2: BONNEY WATSON
B3: Washington Memorial
B4: 16445 International Blvd.
B5: SeaTac, WA 98188
B6: Telephone: (206) 242-1787
B7: Fax: (206) 242-1791
B8: HOLD HARMLESS AGREEMENT
B11: I, | H11: am the owner or representative as listed on the Waiver of Rights for
B12: the property listed below.
D14: =Information!G42 -> 0
B16: In and part of WASHINGTON MEMORIAL PARK & MORTUARY, INC. ("the Cemetery"), 16445 INTERNATIONAL BLVD, SEATAC, WA 98188.
B18: I do hereby give my permission to place a marker / monument(s) on the above named space(s).
B20: Name(s) on listed marker / monument(s):
B22: Marker / Monument Information:
B23: VENDOR NAME: | I23: MONUMENT(S) SIZE:
I24: TABLET SIZE:
B25: VENDOR PHONE: | I25: BASE SIZE:
B26: MARKER SIZE: | I26: GRANITE FOUNDATION SIZE:
B28: All markers must be pre-approved by the Cemetery Authority before manufacturing. And in addition to placement of above named marker / monument(s) at above named space(s), I AGREE to release and HOLD HARMLESS, the Cemetery from any responsibility regarding the design, deterioration of and/or damage of any kind to the above listed marker / monument(s). Any associated inspection and setting fees need to be paid in full prior to the Cemetery's approval of the memorial proof.
B30: Dated on this day:
B33: Signature:
B35: Address:
B37: City: | G37: State: | J37: Zip Code:
B39: Telephone:
B42: Signature of Witness:
B44: Name of Witness:
B46: Firm Witness Representing: | F46: WASINGTON MEMORIAL PARK & MORTUARY, INC.

Sheet Basic Service Folders 
A1: FOLDER ORDERING FORM
A2: Product | B2: BASIC SERVICE FOLDERS
A3: Size | B3: Large
A4: Theme | D4: One | E4: Two
A5: Quantity (Minimum 100)
A6: Paper | B6: Stock
A7: Outside Color | D7: Charcoal | E7: Rose | F7: Taupe
A8: Inside Color | D8: Charcoal | E8: Rose | F8: Taupe
A9: Front Cover Text | B9: =Information!E6&" "&" "&Information!L6&" "&Information!R6
B10: Born
B11: Died
A12: Inside Left Text
A13: Inside Right Text
A14: Back Cover Text
A15: Front Cover Picture
A16: Location | D16: Washington Memorial Park | E16: Capitol Hill | F16: Parker Chapel (Burien) | G16: Federal Way | H16: Wiggen and Sons | I16: Bellevue
A17: Time / Date Needed
A18: Comments
A20: email request to soundmemorial@gmail.com
A22: Emailed by:
A23: Email date:

Sheet Premium Service Folders
A1: FOLDER ORDERING FORM
A2: Product | B2: PREMIUM SERVICE FOLDERS
A3: Size | D3: Large | E3: Small
A4: Theme | D4: Ballard Pride | E4: Elegant 1 | F4: Elegant 2 | G4: Fall Leaves | H4: Flowers One | I4: Green | J4: Sky / Clouds | K4: Zen
A5: Quantity (Minimum 100)
A6: Paper | D6: Matte | E6: Gloss
A7: Front Cover Text | B7: =Information!E6&" "&" "&Information!L6&" "&Information!R6
B8: Born
B9: Died
A10: Inside Left Text
A11: Inside Right Text
A12: Back Cover Text
A13: Front Cover Picture
A14: Location | D14: Washington Memorial Park | E14: Capitol Hill | F14: Parker Chapel (Burien) | G14: Federal Way | H14: Wiggen and Sons | I14: Bellevue
A15: Time / Date Needed
A16: Comments
A18: email request to soundmemorial@gmail.com
A20: Emailed by:
A21: Email date:

Sheet Thank You Card
A1: THANK YOU CARD ORDERING FORM
A2: Product | B2: THANK YOU CARD
A3: Size | B3: Small | D3: Large | E3: Small
A4: Theme | D4: Ballard Pride | E4: Elegant 1 | F4: Elegant 2 | G4: Fall Leaves | H4: Flowers One | I4: Green | J4: Sky / Clouds | K4: Zen
A5: Quantity (Minimum 100)
A6: Paper | D6: Matte | E6: Gloss
A7: Front Cover Text | B7: Thank You
B8: =Information!E6&" "&" "&Information!L6&" "&Information!R6
B9: Born
B10: Died
A11: Inside Right Text
A12: Picture
A13: Location | D13: Washington Memorial Park | E13: Capitol Hill | F13: Parker Chapel (Burien) | G13: Federal Way | H13: Wiggen and Sons | I13: Bellevue
A14: Time / Date Needed
A15: Comments
A17: email request to soundmemorial@gmail.com
A19: Emailed by:
A20: Email date:

Sheet Prayer Card
A1: PRAYER CARD ORDERING FORM
A2: Product | B2: PRAYER CARD
A3: Theme | D3: Ballard Pride | E3: Elegant 1 | F3: Elegant 2 | G3: Fall Leaves | H3: Flowers One | I3: Green | J3: Sky / Clouds | K3: Zen
A4: Quantity (Minimum 100)
A5: Front Cover Text | B5: =Information!E6&" "&" "&Information!L6&" "&Information!R6
B6: Born
B7: Died
A8: Back Text
A9: Location | D9: Washington Memorial Park | E9: Capitol Hill | F9: Parker Chapel (Burien) | G9: Federal Way | H9: Wiggen and Sons | I9: Bellevue
A10: Time / Date Needed
A11: Comments
A13: email request to soundmemorial@gmail.com
A15: Emailed by:
A16: Email date:

Sheet DVD
A1: FOLDER ORDERING FORM
A2: Product | B2: MEMORIAL DVD
A3: External Theme | D3: Ballard Pride | E3: Elegant 1 | F3: Elegant 2 | G3: Fall Leaves | H3: Flowers One | I3: Green | J3: Sky / Clouds | K3: Zen
A4: Internal Theme | B4: DVD Theme 2
A5: Quantity
A6: Songs Requested
A7: Front Cover Text | B7: =Information!E6&" "&" "&Information!L6&" "&Information!R6
B8: Born
B9: Died
A10: Location | D10: Washington Memorial Park | E10: Capitol Hill | F10: Parker Chapel (Burien) | G10: Federal Way | H10: Wiggen and Sons | I10: Bellevue
A11: Time / Date Needed
A12: Comments
A14: email request to soundmemorial@gmail.com
A16: Emailed by:
A17: Email date:

Sheet Items for drop down menu
A2: 8th grade or less: 1st Grade
A3: 8th grade or less: 2nd Grade
A4: 8th grade or less: 3rd Grade
A5: 8th grade or less: 4th Grade
A6: 8th grade or less: 5th Grade
A7: 8th grade or less: 6th Grade
A8: 8th grade or less: 7th Grade
A9: 8th grade or less: 8th Grade
A10: 9th - 12th grade; no diploma
A11: High school graduate or GED completed
A12: Some college credit, but no degree
A13: Associate degree (e.g., AA, AS)
... A149: 70 years

Sheet LEGEND - SVC COMING FROM
A2: BW Federal Way | C2: BW Washington Memorial
A3: BW Greenlake | C3: BW Federal Way
A4: BW Southwest | C4: Outside FH (Enter Below)
A5: BW Washington Memorial
A6: BW Wiggen
A7: A Sacred Moment
A8: Acheson & Grahan
A9: Airesman Hires FH
A10: American Memorial
A11: Autumn FH
A12: Baird FH
A13: Barton FH
A14: Becks FH
A15: Bel Air FH
A16: Bleitz FH
... A89: OTHER

Sheet IOA Legend
A1: Interment Type | B1: Status of CHR | C1: Outer Burial Container | D1: Emblems | E1: Service Type | F1: Service Coming From | G1: Relationship | I1: Memorial Type | K1: Granite Marker Size | L1: Granite Foundation Size | M1: Bronze Marker Size | N1: Upright Size | O1: Upright Tablet Finish | P1: Upright Tablet Shape | Q1: Upright Base Finish | R1: Granite Color | S1: Bench Size and Style
A3: Aquamation | B3: N/A | C3: N/A | D3: N/A | E3: At our Convenience (AOC) | F3: WMFH Chapel | G3: Husband | H3: YES | I3: Flat Marker | K3: 16 x 8 | L3: 28 x 16 | M3: 24 x 12 | N3: Tablet: 18x6 24 / Base: 26x12x6 | O3: P2 BRP | P3: Flat Top | Q3: PFT BRP | R3: Absolute Black | S3: Seat 36x14x4 / Pedestal 30x8x14
A4: Lawn Crypt Interment | B4: CHR at WMP | C4: Bronze Triune | D4: American Legion | E4: D.O. – Delivery Only | F4: O/S Funeral Home | G4: Wife | H4: NO | I4: Bronze on Granite | K4: 18 x 10 | L4: 28 x 38 | M4: 28 x 16 | N4: Tablet: 20x6x18 / Base: 26x12x6 | O4: P3 BRP | P4: Oval Top | Q4: Steeled Top BRP | R4: Academy Black | S4: Seat 42x14x4 / Pedestal 36x8x14
A5: Lawn Crypt Interment | B5: Family will Bring CHR | C5: Cameo Rose Triune | D5: Cross | E5: Full Service (F.S.) | F5: Church | G5: Spouse | I5: Upright with Base | K5: 24 x 12 Govt or Govt match | L5: 60 x 16 | M5: 28 x 18 | N5: Tablet: 20x8x28 / Base: 28x14x8 | O5: P5 | P5: Serp Top | Q5: All Polished | R5: Aurora | S5: Seat 48x14x4 / Pedestal 40x8x14
A6: Lawn Crypt Inurnment | B6: Pending Cremation at BW | C6: Continental | D6: Crucifix | E6: Full Service Crypt (FSC) | G6: Son | I6: Bench | K6: 28 x 16 | L6: 64 x 20 | M6: 32 x 20 | N6: Tablet: 24x6x18 / Base: 30x12x6 | O6: Matte 2 BRP | R6: Bahama Blue | S6: Seat 60x14x4 / Pedestal 50x8x14
A7: Lawn Interment | C7: Copper Triune | D7: Dove of Peace | E7: Full Service Graveside (FSG) | G7: Daughter | I7: Custom | K7: 28 x 34 | L7: N/A | M7: 36 x 76 | N7: Tablet: 24x8x36 / Base: 30x14x8 | O7: Matte 3 BRP | R7: Barrell Gray | S7: Seat 36x14x4 / Straight Legs 12x4x14
A8: Lawn Inurnment | C8: Infant Liner | D8: Eagles | E8: Full Service Niche (FSN) | G8: Sister | K8: 32 x 20 | M8: 48 x 18 | N8: Tablet: 36x6x24 / Base: 48x12x6 | O8: Matte 5 | R8: Black Galaxy | S8: Seat 48x14x4 / Straight Legs 12x4x14
A9: Mausoleum Entombment | C9: Infant Loved & Cherished 19" | D9: Eastern Star | E9: Graveside Service (G.S.) | G9: Brother | K9: 36 x 18 | M9: 64 x 20 | N9: Tablet: 36x8x24 / Base: 48x14x8 | R9: Cascade Gray | S9: Seat 60x14x4 / Stright Legs 12x4x14
A10: Mausoleum Inurnment | C10: Infant Loved & Cherished 24" | D10: Elks | E10: Graveside Service Graveside (GSG) | G10: Father | K10: 36 x 72 | M10: 32 x 72 | N10: Tablet: 48x8x28 / Base: 60x14x8 | R10: Cat's Eye | S10: Curved Seat 36x14x4 / Harp Legs 12x4x14
A11: Niche Inurnment | C11: Infant Loved & Cherished 31" | D11: Independent Order of Odd Fellows | E11: Graveside Service Lobby (GSL) | G11: Mother | K11: 40 x 16 | M11: N/A | N11: Tablet: 48x8x36 / Base: 60x14x8 | R11: Classic Gray | S11: Curved Seat 48x14x4 / Harp Legs 12x4x14
A12: Scattering | C12: Marbelon Urn/Vault - Octagon | D12: Knights of Columbus | E12: Witness (WIT) | G12: Son in law | K12: 44 x 20 | N12: Tablet: 60x8x36 / Base: 72x148x | R12: Cloud White | S12: Curved Seat 60x14x4 / Harp Legs 12x4x14
A13: Terramation | C13: Marbelon Urn/Vault - Rectangle | D13: Masonic | E13: Witness Cremation (WIT C) | G13: Daughter in law | K13: 60 x 20 | R13: Impala Black | S13: 36^ Four Piece Garden Bench
C14: Marbelon Urn/Vault - Universal | D14: Moose | E14: Witness Lowering (WIT L) | G14: Step Son | K14: N/A | R14: Imperial Red | S14: 48" Four Piece Garden Bench
C15: Monarch | D15: Praying Hands | E15: Witness Placement (WIT P) | G15: Step Daughter | R15: PC Violet
C16: Monticello B.V. | D16: Roses | G16: Aunt | R16: Maple Red
C17: Oversize Monticello B.V. | D17: Russian Orthodox Cross | G17: Uncle | R17: Misty Pink
C18: Oversized Concrete | D18: Shrine | G18: Niece | R18: Mocha
C19: SST Triune | D19: Star of David | G19: Nephew | R19: New Mahogany
C20: Standard Concrete | D20: US Air Force | G20: Grandmother | R20: Paradiso
C21: The Salute | D21: US Marine Corps | G21: Grandfather | R21: Sapphire Brown
C22: The Veteran (Triune) | D22: US Navy | G22: Granddaughter | R22: Sentinel Red
C23: Venetian | D23: Veterans of Foreign Wars | G23: Grandson | R23: Sierra White
C24: Wilbert Bronze | D24: Wreath | G24: Great Grandmother | R24: Silver Bronze
C25: Wilbert Cameo Rose Urn Vault | G25: Great Grandfather | R25: Taxn Brown
C26: Wilbert Monticello Urn Vault 12" | G26: Brother-In-Law | R26: Twilight Red
C27: Wilbert Monticello Urn Vault 18" | G27: Sister-In-Law | R27: Tropical Green
C28: Wilbert Stainless Steel Triune UV | G28: Guardian | R28: Wiscont White
C29: Wilbert Tribute Vault | G29: Friend | R29: Aspen White
C30: Wilbert Triune Urn Vault | G30: Cousin | R30: Blue Butterfly
C31: Wilbert Universal Urn Vault | G31: Partner | R31: Blue Pearl
C32: Wilbert Venetian Urn Vault 12" | G32: None | R32: Blue Star
C33: Wilbert Venetian Urn Vault 18" | R33: Classic Dark Gray
C34: Wilbert Veteran Triune Urn Vault | R34: New Classic Pink
R35: Georgia Gray
R36: Himalaya Blue
R37: New Dark Gray
R38: New Diana Green
R39: Night Black
R40: Peacock Green
R41: Rainbow Red
...

Sheet GARDENS ETC.
A1: 6 | B1: SUNRISE GARDEN (6)
A2: 7 | B2: LAKESIDE GARDEN (7)
A3: 8 | B3: GARDEN OF MEMORIES (8)
A4: 9 | B4: GARDEN OF HOPE (9)
A5: 10 | B5: GARDEN OF REFLECTION (10)
A6: 11 | B6: GARDEN OF DEVOTION (11)
A7: 12 | B7: GARDEN OF THE GOOD SHEPHERD (12)
A8: 13 | B8: FRIENDSHIP GARDEN (13)
A9: 14 | B9: GARDEN OF MEDITATION (14)
A10: 15 | B10: GARDEN OF COMMUNION (15)
A11: 16 | B11: SUNSET GARDEN (16)
A12: 17 | B12: SUNDIAL GARDEN (17)
... A57: VETSM | B57: VETERANS MONUMENT NICHES

Sheet Sheet2

Sheet Drop-downs
A1: Memorial Colors | B1: Granite Memorial Sizes | C1: Granite Base Sizes | D1: Bronze Memorial Sizes | E1: Vases | F1: Rings | G1: Design # | H1: Inscription | I1: Bases | L1: Manufacturers
A3: Group I | B3: 60 x 20 | C3: 64 x 20 | D3: 56 x 16 | E3: Grecian | F3: Grecian | G3: Q1001 | H3: Inscribed | I3: Granite | J3: Moonlight Grey | K3: Standard Light | L3: Matthews
A4: Georgia Gray | G4: Q1002
B5: 40 x 16 | C5: 60 x 20 | D5: 44 x 14 | E5: Veterans | F5: Veterans | G5: Q1003 | H5: Monobar | I5: Concrete | J5: Concrete | K5: Medium | L5: Trinity
A6: Sierra White | G6: Q1004 | H6: Staff Bar
B7: 36 x 18 | C7: 48 x 18 | D7: 28 x 16 | E7: Plain Doric | F7: Plain | G7: Q1005 | H7: Bronze Plate | K7: Dark | L7: OBW
A8: Mahogany | G8: Q1006
B9: 36 x 72 | C9: 28 x 38 | D9: 24 x 14 | E9: Hammered Doric | F9: Hammered | G9: Q1007 | K9: Light | L9: Gorham
A10: Group II | G10: Q1008
B11: 28 x 34 | C11: 28 x 18 | D11: 24 x 12 | E11: Gray Zinc (NR) | F11: Rock-edged | G11: Q1009 | L11: Williamsburg
A12: Sentinel Red | G12: Q1010
B13: 28 x 16 | C13: 28 x 16 | D13: 16 x 24 | E13: Rolled Copper (NR) | F13: Floral Innocence | G13: Q1011 | L13: Gasser-Olds
A14: Rainbow | G14: Q1012
B15: 24 x 12 | C15: 20 x 28 | D15: 16 x 8 | E15: Floral Innocence | G15: Q1013 | L15: Quiring
A16: Tropical Green | G16: Q1014
B17: 18 x 10 | C17: 17 x 23 | D17: 12 x 12 | G17: Q1015 | L17: Granit-Bronz
A18: Barre | G18: Q1016
B19: 16 x 8 | C19: 40 x 36 | D19: 15 x 10 | G19: Q1017 | L19: York
A20: Galaxy Black | G20: Q1018
C21: 40 x 76 | D21: 11.5 x 17 | G21: Q1019 | L21: Unknown
A22: Charcoal Black | G22: Q1020
C23: 15 x 10 | D23: 24 x 30 | G23: Q1021
A24: Ebony Mist | G24: Q1022
C25: 14 x 14 | D25: 36 x 72 | G25: Q1023
A26: Gray St. Cloud | G26: Q1024
C27: 16 x 8 | G27: Q1025
A28: Group III | G28: Q1026
A29: Wausau | C29: 14 x 14 | G29: Q1027
G30: Q1028
A31: Blue Pearl | G31: Q1029
G32: Q1030
A33: Gorman Green | G33: Q1031
G34: Q1032
G35: Q1033
G36: Q1034
G37: Q1035
G38: Q1036
G39: Q1037
G40: Q1038
G41: Q1039
...

Sheet Sheet1
